2025-06-25 03:54:15,304 INFO    MainThread:58772 [wandb_setup.py:_flush():67] Current SDK version is 0.19.8
2025-06-25 03:54:15,305 INFO    MainThread:58772 [wandb_setup.py:_flush():67] Configure stats pid to 58772
2025-06-25 03:54:15,305 INFO    MainThread:58772 [wandb_setup.py:_flush():67] Loading settings from /Users/zhongyeah/.config/wandb/settings
2025-06-25 03:54:15,305 INFO    MainThread:58772 [wandb_setup.py:_flush():67] Loading settings from /Users/zhongyeah/Documents/Research/Ban/model/wandb/settings
2025-06-25 03:54:15,305 INFO    MainThread:58772 [wandb_setup.py:_flush():67] Loading settings from environment variables
2025-06-25 03:54:15,305 INFO    MainThread:58772 [wandb_init.py:setup_run_log_directory():647] Logging user logs to /Users/zhongyeah/Documents/Research/Ban/model/wandb/run-20250625_035415-6yir0xar/logs/debug.log
2025-06-25 03:54:15,305 INFO    MainThread:58772 [wandb_init.py:setup_run_log_directory():648] Logging internal logs to /Users/zhongyeah/Documents/Research/Ban/model/wandb/run-20250625_035415-6yir0xar/logs/debug-internal.log
2025-06-25 03:54:15,305 INFO    MainThread:58772 [wandb_init.py:init():761] calling init triggers
2025-06-25 03:54:15,305 INFO    MainThread:58772 [wandb_init.py:init():766] wandb.init called with sweep_config: {}
config: {'architecture': 'ResNet18-MultiTask', 'dataset': 'robot_state', 'epochs': 50, 'batch_size': 32, 'learning_rate': 0.001, 'weight_decay': 1e-05, 'state_weight': 3.0, 'task_weight': 1.0, 'optimizer': 'Adam', 'scheduler': 'ReduceLROnPlateau', '_wandb': {}}
2025-06-25 03:54:15,305 INFO    MainThread:58772 [wandb_init.py:init():784] starting backend
2025-06-25 03:54:15,305 INFO    MainThread:58772 [wandb_init.py:init():788] sending inform_init request
2025-06-25 03:54:15,338 INFO    MainThread:58772 [backend.py:_multiprocessing_setup():101] multiprocessing start_methods=spawn,fork,forkserver, using: spawn
2025-06-25 03:54:15,339 INFO    MainThread:58772 [wandb_init.py:init():798] backend started and connected
2025-06-25 03:54:15,341 INFO    MainThread:58772 [wandb_init.py:init():891] updated telemetry
2025-06-25 03:54:15,342 INFO    MainThread:58772 [wandb_init.py:init():915] communicating run to backend with 90.0 second timeout
2025-06-25 03:54:46,318 INFO    Thread-2 (wrapped_target):58772 [retry.py:__call__():175] Retry attempt failed:
Traceback (most recent call last):
  File "/opt/anaconda3/envs/txt/lib/python3.10/site-packages/urllib3/connection.py", line 198, in _new_conn
    sock = connection.create_connection(
  File "/opt/anaconda3/envs/txt/lib/python3.10/site-packages/urllib3/util/connection.py", line 85, in create_connection
    raise err
  File "/opt/anaconda3/envs/txt/lib/python3.10/site-packages/urllib3/util/connection.py", line 73, in create_connection
    sock.connect(sa)
TimeoutError: timed out

The above exception was the direct cause of the following exception:

Traceback (most recent call last):
  File "/opt/anaconda3/envs/txt/lib/python3.10/site-packages/urllib3/connectionpool.py", line 787, in urlopen
    response = self._make_request(
  File "/opt/anaconda3/envs/txt/lib/python3.10/site-packages/urllib3/connectionpool.py", line 488, in _make_request
    raise new_e
  File "/opt/anaconda3/envs/txt/lib/python3.10/site-packages/urllib3/connectionpool.py", line 464, in _make_request
    self._validate_conn(conn)
  File "/opt/anaconda3/envs/txt/lib/python3.10/site-packages/urllib3/connectionpool.py", line 1093, in _validate_conn
    conn.connect()
  File "/opt/anaconda3/envs/txt/lib/python3.10/site-packages/urllib3/connection.py", line 704, in connect
    self.sock = sock = self._new_conn()
  File "/opt/anaconda3/envs/txt/lib/python3.10/site-packages/urllib3/connection.py", line 207, in _new_conn
    raise ConnectTimeoutError(
urllib3.exceptions.ConnectTimeoutError: (<urllib3.connection.HTTPSConnection object at 0x3027e1120>, 'Connection to api.wandb.ai timed out. (connect timeout=20)')

The above exception was the direct cause of the following exception:

Traceback (most recent call last):
  File "/opt/anaconda3/envs/txt/lib/python3.10/site-packages/requests/adapters.py", line 667, in send
    resp = conn.urlopen(
  File "/opt/anaconda3/envs/txt/lib/python3.10/site-packages/urllib3/connectionpool.py", line 841, in urlopen
    retries = retries.increment(
  File "/opt/anaconda3/envs/txt/lib/python3.10/site-packages/urllib3/util/retry.py", line 519, in increment
    raise MaxRetryError(_pool, url, reason) from reason  # type: ignore[arg-type]
urllib3.exceptions.MaxRetryError: HTTPSConnectionPool(host='api.wandb.ai', port=443): Max retries exceeded with url: /graphql (Caused by ConnectTimeoutError(<urllib3.connection.HTTPSConnection object at 0x3027e1120>, 'Connection to api.wandb.ai timed out. (connect timeout=20)'))

During handling of the above exception, another exception occurred:

Traceback (most recent call last):
  File "/opt/anaconda3/envs/txt/lib/python3.10/site-packages/wandb/sdk/lib/retry.py", line 134, in __call__
    result = self._call_fn(*args, **kwargs)
  File "/opt/anaconda3/envs/txt/lib/python3.10/site-packages/wandb/sdk/internal/internal_api.py", line 398, in execute
    return self.client.execute(*args, **kwargs)  # type: ignore
  File "/opt/anaconda3/envs/txt/lib/python3.10/site-packages/wandb/vendor/gql-0.2.0/wandb_gql/client.py", line 52, in execute
    result = self._get_result(document, *args, **kwargs)
  File "/opt/anaconda3/envs/txt/lib/python3.10/site-packages/wandb/vendor/gql-0.2.0/wandb_gql/client.py", line 60, in _get_result
    return self.transport.execute(document, *args, **kwargs)
  File "/opt/anaconda3/envs/txt/lib/python3.10/site-packages/wandb/sdk/lib/gql_request.py", line 58, in execute
    request = self.session.post(self.url, **post_args)
  File "/opt/anaconda3/envs/txt/lib/python3.10/site-packages/requests/sessions.py", line 637, in post
    return self.request("POST", url, data=data, json=json, **kwargs)
  File "/opt/anaconda3/envs/txt/lib/python3.10/site-packages/requests/sessions.py", line 589, in request
    resp = self.send(prep, **send_kwargs)
  File "/opt/anaconda3/envs/txt/lib/python3.10/site-packages/requests/sessions.py", line 703, in send
    r = adapter.send(request, **kwargs)
  File "/opt/anaconda3/envs/txt/lib/python3.10/site-packages/requests/adapters.py", line 688, in send
    raise ConnectTimeout(e, request=request)
requests.exceptions.ConnectTimeout: HTTPSConnectionPool(host='api.wandb.ai', port=443): Max retries exceeded with url: /graphql (Caused by ConnectTimeoutError(<urllib3.connection.HTTPSConnection object at 0x3027e1120>, 'Connection to api.wandb.ai timed out. (connect timeout=20)'))
2025-06-25 03:54:49,592 WARNING MainThread:58772 [wandb_init.py:init():1472] interrupted
Traceback (most recent call last):
  File "/opt/anaconda3/envs/txt/lib/python3.10/site-packages/wandb/sdk/wandb_init.py", line 1468, in init
    return wi.init(run_settings, run_config)
  File "/opt/anaconda3/envs/txt/lib/python3.10/site-packages/wandb/sdk/wandb_init.py", line 941, in init
    result = wait_with_progress(
  File "/opt/anaconda3/envs/txt/lib/python3.10/site-packages/wandb/sdk/mailbox/wait_with_progress.py", line 24, in wait_with_progress
    return wait_all_with_progress(
  File "/opt/anaconda3/envs/txt/lib/python3.10/site-packages/wandb/sdk/mailbox/wait_with_progress.py", line 87, in wait_all_with_progress
    return asyncio_compat.run(progress_loop_with_timeout)
  File "/opt/anaconda3/envs/txt/lib/python3.10/site-packages/wandb/sdk/lib/asyncio_compat.py", line 30, in run
    return future.result()
  File "/opt/anaconda3/envs/txt/lib/python3.10/concurrent/futures/_base.py", line 453, in result
    self._condition.wait(timeout)
  File "/opt/anaconda3/envs/txt/lib/python3.10/threading.py", line 320, in wait
    waiter.acquire()
KeyboardInterrupt
2025-06-25 03:54:50,419 INFO    MsgRouterThr:58772 [mailbox.py:close():129] Closing mailbox, abandoning 1 handles.
